<?xml version="1.0"?>

<robot name="diff_robot" xmlns:xacro="http://www.ros.org/wiki/xacro">

  <!--All units in m-kg-s-radians unit system -->
  <xacro:property name="M_PI" value="3.1415926535897931" />
  <xacro:property name="M_PI_2" value="1.570796327" />
  <xacro:property name="DEG_TO_RAD" value="0.017453293" />

	<!--Material Definition-->  
	<material name="Black">
	  <color rgba="0.0 0.0 0.0 1.0"/>
	</material>

  <material name="Red">
  	<color rgba="0.8 0.0 0.0 1.0"/>
  </material>

  <material name="White">
    <color rgba="1.0 1.0 1.0 1.0"/>
  </material>

  <material name="Blue">
    <color rgba="0.0 0.0 0.8 1.0"/>
  </material>

  <!-- Base properties -->
	<xacro:property name="base_height" value="0.02" /> 
  <xacro:property name="base_radius" value="0.15" /> 
  <xacro:property name="base_mass" value="5" />

  <!-- caster wheel proprieties  -->
  <xacro:property name="caster_height" value="0.04" /> 
  <xacro:property name="caster_radius" value="0.025" /> 
  <xacro:property name="caster_mass" value="0.5" /> <!-- in kg-->
  
  <!-- Wheels -->
  <xacro:property name="wheel_radius" value="0.039" /> 
  <xacro:property name="wheel_height" value="0.02" />
  <xacro:property name="wheel_mass" value="2.5" /> <!-- in kg-->
  
  <xacro:property name="base_x_origin_to_wheel_origin" value="0.25" />
  <xacro:property name="base_y_origin_to_wheel_origin" value="0.3" />
  <xacro:property name="base_z_origin_to_wheel_origin" value="0.0" />

  <xacro:macro name="cylinder_inertia" params="m r h">
    <inertia  ixx="${m*(3*r*r+h*h)/12}" ixy = "0" ixz = "0"
              iyy="${m*(3*r*r+h*h)/12}" iyz = "0"
              izz="${m*r*r/2}" /> 
  </xacro:macro>


	<xacro:macro name="caster_joint" params="name parent child *origin">
		<joint name="${name}" type="fixed" >
			<parent link="${parent}" />
			<child link="${child}" />
	    <xacro:insert_block name="origin" />
		</joint>
	</xacro:macro>

	<xacro:macro name="caster_link" params="name *origin">
		<link name="${name}">
			<visual>
	    	<xacro:insert_block name="origin" />
				<geometry>
					<sphere radius="${caster_radius}" />
				</geometry>
				<material name="Black" />
			</visual>  
			<collision>
				<geometry>
					<sphere radius="${caster_radius}" />
				</geometry>
				<origin xyz="0 0.02 0" rpy="${M_PI/2} 0 0" />
			</collision>      
			<inertial>
				<mass value="${caster_mass}" />
				<origin xyz="0 0 0" />
					<inertia  ixx="0.001" ixy="0.0" ixz="0.0"
						  			iyy="0.001" iyz="0.0" 
 										izz="0.001" />
			</inertial>
		</link>
	</xacro:macro>
	
  <xacro:macro name="wheel" params="fb lr parent translateX translateY flipY"> <!--fb : front, back ; lr: left, right -->
    <link name="${fb}_${lr}_wheel">
      <visual>
        <origin xyz="0 0 0" rpy="${flipY*M_PI/2} 0  0 " /> 
        <geometry>
          <cylinder length="${wheel_height}" radius="${wheel_radius}" />
        </geometry>
        <material name="DarkGray" />
      </visual>
      <collision>
        <origin xyz="0 0 0" rpy="${flipY*M_PI/2} 0 0 " />
        <geometry>
          <cylinder length="${wheel_height}" radius="${wheel_radius}" />
        </geometry>
      </collision>
      <inertial>
        <mass value="${wheel_mass}" />
        <origin xyz="0 0 0" />
				<inertia ixx="0.001" ixy="0.0" ixz="0.0"
               iyy="0.001" iyz="0.0" 
               izz="0.001" />
      </inertial>
    </link>

    <gazebo reference="${fb}_${lr}_wheel">
      <mu1 value="1.0"/>
      <mu2 value="1.0"/>
      <kp  value="10000000.0" />
      <kd  value="1.0" />
      <fdir1 value="1 0 0"/>
      <material>Gazebo/Grey</material>
      <turnGravityOff>false</turnGravityOff>
    </gazebo>

    <joint name="${fb}_${lr}_wheel_joint" type="continuous">
      <parent link="${parent}"/>
      <child link="${fb}_${lr}_wheel"/>
      <origin xyz="${translateX * base_x_origin_to_wheel_origin} ${translateY * base_y_origin_to_wheel_origin} ${base_z_origin_to_wheel_origin}" rpy="0 0 0" /> 
      <axis xyz="0 1 0" rpy="0 0 0" />
      <limit effort="100" velocity="100"/>
      <joint_properties damping="0.0" friction="0.0"/>
    </joint>

    <!-- Transmission is important to link the joints and the controller -->
    <transmission name="${fb}_${lr}_wheel_joint_trans">
      <type>transmission_interface/SimpleTransmission</type>
      <joint name="${fb}_${lr}_wheel_joint" />
      <actuator name="${fb}_${lr}_wheel_joint_motor">
        <hardwareInterface>EffortJointInterface</hardwareInterface>
        <mechanicalReduction>1</mechanicalReduction>
      </actuator>
    </transmission>
  </xacro:macro>
</robot>

